<?xml version="1.0" encoding="utf-8"?>
<!-- This URDF was automatically created by SolidWorks to URDF Exporter! Originally created by Stephen Brawner (brawner@gmail.com) 
     Commit Version: 1.6.0-4-g7f85cfe  Build Version: 1.6.7995.38578
     For more information, please see http://wiki.ros.org/sw_urdf_exporter -->
<robot
  name="IRB 1300-1150 URDF">
  <link
    name="base_link">
    <inertial>
      <origin
        xyz="-0.02201 -0.00063839 0.1276"
        rpy="0 0 0" />
      <mass
        value="13.182" />
      <inertia
        ixx="0.11154"
        ixy="-0.00041958"
        ixz="-0.0029321"
        iyy="0.12833"
        iyz="-3.0692E-05"
        izz="0.10399" />
    </inertial>
    <visual>
      <origin
        xyz="0 0 0"
        rpy="0 0 0" />
      <geometry>
        <mesh
          filename="package://IRB 1300-1150 URDF/meshes/base_link.STL" />
      </geometry>
      <material
        name="">
        <color
          rgba="1 1 1 1" />
      </material>
    </visual>
    <collision>
      <origin
        xyz="0 0 0"
        rpy="0 0 0" />
      <geometry>
        <mesh
          filename="package://IRB 1300-1150 URDF/meshes/base_link.STL" />
      </geometry>
    </collision>
  </link>
  <link
    name="Link1">
    <inertial>
      <origin
        xyz="0.0379140465011304 -0.00077346865336323 0.145882231183446"
        rpy="0 0 0" />
      <mass
        value="16.3325331099999" />
      <inertia
        ixx="0.174362024179828"
        ixy="0.0183368936461501"
        ixz="-0.0552544146231136"
        iyy="0.208069036216912"
        iyz="0.0360494323577949"
        izz="0.165549084912184" />
    </inertial>
    <visual>
      <origin
        xyz="0 0 0"
        rpy="0 0 0" />
      <geometry>
        <mesh
          filename="package://IRB 1300-1150 URDF/meshes/Link1.STL" />
      </geometry>
      <material
        name="">
        <color
          rgba="1 1 1 1" />
      </material>
    </visual>
    <collision>
      <origin
        xyz="0 0 0"
        rpy="0 0 0" />
      <geometry>
        <mesh
          filename="package://IRB 1300-1150 URDF/meshes/Link1.STL" />
      </geometry>
    </collision>
  </link>
  <joint
    name="Joint1"
    type="revolute">
    <origin
      xyz="0 0 0.254"
      rpy="0 0 0" />
    <parent
      link="base_link" />
    <child
      link="Link1" />
    <axis
      xyz="0 0 1" />
    <limit
      lower="-3.1416"
      upper="3.1416"
      effort="1"
      velocity="1" />
  </joint>
  <link
    name="Link2">
    <inertial>
      <origin
        xyz="-0.010943302471405 -0.000823452736931489 0.244958725841501"
        rpy="0 0 0" />
      <mass
        value="15.4405289883218" />
      <inertia
        ixx="0.454189406801351"
        ixy="0.000833807793902255"
        ixz="0.00519621446900202"
        iyy="0.446840533249867"
        iyz="0.0465559640262711"
        izz="0.0564311207928579" />
    </inertial>
    <visual>
      <origin
        xyz="0 0 0"
        rpy="0 0 0" />
      <geometry>
        <mesh
          filename="package://IRB 1300-1150 URDF/meshes/Link2.STL" />
      </geometry>
      <material
        name="">
        <color
          rgba="1 1 1 1" />
      </material>
    </visual>
    <collision>
      <origin
        xyz="0 0 0"
        rpy="0 0 0" />
      <geometry>
        <mesh
          filename="package://IRB 1300-1150 URDF/meshes/Link2.STL" />
      </geometry>
    </collision>
  </link>
  <joint
    name="Joint2"
    type="revolute">
    <origin
      xyz="0.15 0 0.29"
      rpy="0 0 0" />
    <parent
      link="Link1" />
    <child
      link="Link2" />
    <axis
      xyz="0 1 0" />
    <limit
      lower="-1.6581"
      upper="2.7053"
      effort="1"
      velocity="1" />
  </joint>
  <link
    name="Link3">
    <inertial>
      <origin
        xyz="0.00583162917002927 -0.00131958947797208 0.0114105778753493"
        rpy="0 0 0" />
      <mass
        value="4.41745625966426" />
      <inertia
        ixx="0.0147798858809225"
        ixy="-5.10577958981008E-05"
        ixz="-0.00147588390166233"
        iyy="0.0217907531368722"
        iyz="-0.000100030526636097"
        izz="0.0184719400306652" />
    </inertial>
    <visual>
      <origin
        xyz="0 0 0"
        rpy="0 0 0" />
      <geometry>
        <mesh
          filename="package://IRB 1300-1150 URDF/meshes/Link3.STL" />
      </geometry>
      <material
        name="">
        <color
          rgba="1 1 1 1" />
      </material>
    </visual>
    <collision>
      <origin
        xyz="0 0 0"
        rpy="0 0 0" />
      <geometry>
        <mesh
          filename="package://IRB 1300-1150 URDF/meshes/Link3.STL" />
      </geometry>
    </collision>
  </link>
  <joint
    name="Joint3"
    type="revolute">
    <origin
      xyz="0 0 0.575"
      rpy="0 0 0" />
    <parent
      link="Link2" />
    <child
      link="Link3" />
    <axis
      xyz="0 1 0" />
    <limit
      lower="-3.6652"
      upper="1.1345"
      effort="1"
      velocity="1" />
  </joint>
  <link
    name="Link4">
    <inertial>
      <origin
        xyz="0.140260635359611 -0.00136562560352289 0.00129646301386632"
        rpy="0 0 0" />
      <mass
        value="3.69431402699864" />
      <inertia
        ixx="0.00541702840019788"
        ixy="0.00158652277591609"
        ixz="8.51527721227943E-05"
        iyy="0.0298154184956188"
        iyz="-2.11291150182165E-05"
        izz="0.0280131784820624" />
    </inertial>
    <visual>
      <origin
        xyz="0 0 0"
        rpy="0 0 0" />
      <geometry>
        <mesh
          filename="package://IRB 1300-1150 URDF/meshes/Link4.STL" />
      </geometry>
      <material
        name="">
        <color
          rgba="1 1 1 1" />
      </material>
    </visual>
    <collision>
      <origin
        xyz="0 0 0"
        rpy="0 0 0" />
      <geometry>
        <mesh
          filename="package://IRB 1300-1150 URDF/meshes/Link4.STL" />
      </geometry>
    </collision>
  </link>
  <joint
    name="Joint4"
    type="revolute">
    <origin
      xyz="0.128 0 0.04"
      rpy="0 0 0" />
    <parent
      link="Link3" />
    <child
      link="Link4" />
    <axis
      xyz="1 0 0" />
    <limit
      lower="-4.0143"
      upper="4.0143"
      effort="1"
      velocity="1" />
  </joint>
  <link
    name="Link5">
    <inertial>
      <origin
        xyz="0.0204854339056124 0.00887681892988258 5.81633089897782E-05"
        rpy="0 0 0" />
      <mass
        value="0.585190237279786" />
      <inertia
        ixx="0.000493350438723821"
        ixy="6.25796891964945E-05"
        ixz="1.86941748612868E-06"
        iyy="0.000782731233621633"
        iyz="8.97144627802968E-08"
        izz="0.000725967580946081" />
    </inertial>
    <visual>
      <origin
        xyz="0 0 0"
        rpy="0 0 0" />
      <geometry>
        <mesh
          filename="package://IRB 1300-1150 URDF/meshes/Link5.STL" />
      </geometry>
      <material
        name="">
        <color
          rgba="1 1 1 1" />
      </material>
    </visual>
    <collision>
      <origin
        xyz="0 0 0"
        rpy="0 0 0" />
      <geometry>
        <mesh
          filename="package://IRB 1300-1150 URDF/meshes/Link5.STL" />
      </geometry>
    </collision>
  </link>
  <joint
    name="Joint5"
    type="revolute">
    <origin
      xyz="0.297 0 0"
      rpy="0 0 0" />
    <parent
      link="Link4" />
    <child
      link="Link5" />
    <axis
      xyz="0 1 0" />
    <limit
      lower="-2.2689"
      upper="2.2689"
      effort="1"
      velocity="1" />
  </joint>
  <link
    name="Link6">
    <inertial>
      <origin
        xyz="-0.0030397653842329 0.000141388062541223 7.719029081521E-05"
        rpy="0 0 0" />
      <mass
        value="0.00790032012561492" />
      <inertia
        ixx="3.06775217763411E-06"
        ixy="-4.44183698672834E-11"
        ixz="-2.42500450595015E-11"
        iyy="1.59968258334013E-06"
        iyz="-1.16947500504224E-08"
        izz="1.51446478201562E-06" />
    </inertial>
    <visual>
      <origin
        xyz="0 0 0"
        rpy="0 0 0" />
      <geometry>
        <mesh
          filename="package://IRB 1300-1150 URDF/meshes/Link6.STL" />
      </geometry>
      <material
        name="">
        <color
          rgba="1 1 1 1" />
      </material>
    </visual>
    <collision>
      <origin
        xyz="0 0 0"
        rpy="0 0 0" />
      <geometry>
        <mesh
          filename="package://IRB 1300-1150 URDF/meshes/Link6.STL" />
      </geometry>
    </collision>
  </link>
  <joint
    name="Joint6"
    type="revolute">
    <origin
      xyz="0.0900000000000001 0 0"
      rpy="0 0 0" />
    <parent
      link="Link5" />
    <child
      link="Link6" />
    <axis
      xyz="1 0 0" />
    <limit
      lower="-4.2237"
      upper="4.2237"
      effort="1"
      velocity="1" />
  </joint>
  <link name="ee_link" />
  <joint
    name="ee_joint"
    type="fixed">
    <parent link="Link6" />
    <child link="ee_link" />
    <origin xyz="0.09982 0.123 0.0828" rpy="0.0011 0.00039 2.7825" />
  </joint>
</robot>